Workbook
Name angka: #REF!

Sheet Kelas X
D2: DAFTAR NAMA SISWA - SISWI
D3: SMA A. WAHID HASYIM TEBUIRENG JOMBANG
D4: TAHUN PELAJARAN : 2026- 2027
D5: KELAS : X .1 | F5: Wali Kelas : LIHAM HASAN AL MUJAB, S.H
B6: NOMOR | D6: NAMA | E6: L/P
B7: Urut | C7: N I S
B8: 1 | C8: 16383 | D8: ADYPATI NUZHA PUTRA SAFII | E8: L
B9: 2 | C9: 16384 | D9: ALI AMIRUDIN CAHYO | E9: L
B10: 3 | C10: 16385 | D10: ANTASENA BANI NATAATMAJA | E10: L
B11: 4 | C11: 16386 | D11: ARIF HIDAYAT | E11: L
B12: 5 | C12: 16387 | D12: ARIO ABDILLAH MAZHAZ | E12: L
B13: 6 | C13: 16388 | D13: BIMA ARYASENO AR-RASYID | E13: L
B14: 7 | C14: 16389 | D14: DIMAS SAPUTRA | E14: L
B15: 8 | C15: 16390 | D15: FAITH AZARIA AZFA | E15: L
B16: 9 | C16: 16391 | D16: IBRAHIM AINUN M | E16: L
B17: 10 | C17: 16392 | D17: ISNAREJA TURZAITA ZAIN | E17: L
B18: 11 | C18: 16393 | D18: MAHBUB HAYATULLOH NIDZOMI | E18: L
B19: 12 | C19: 16394 | D19: MOCH HALIM HILMI | E19: L
... B34: 27 | C34: 16409 | D34: RASYA ALDIMAN | E34: L
B35: 28 | E35: L
B36: 29 | E36: L
B37: 30 | E37: L
B38: 31 | E38: L
B39: 32 | E39: L
B40: 33 | E40: L
B41: 34 | E41: L
B42: 35 | E42: L
B43: 36 | E43: L
B44: 37 | E44: L
B45: 38 | E45: L
B46: 39 | E46: L
... B48: 41 | E48: L
D51: DAFTAR NAMA SISWA - SISWI
D52: SMA A. WAHID HASYIM TEBUIRENG JOMBANG
D53: TAHUN PELAJARAN : 2026- 2027
D54: KELAS : X. 2 | F54: Wali Kelas : ODIK TUGI HARTONO, S.Pd
B55: NOMOR | D55: NAMA | E55: L/P
B56: Urut | C56: N I S
B57: 1 | C57: 16410 | D57: AHMAD AZAM NUR ZIDAN | E57: L
B58: 2 | C58: 16411 | D58: AHMAD DAFA MAULANA | E58: L
...

Sheet Absen Piket X
D2: DAFTAR NAMA SISWA - SISWI
D3: SMA A. WAHID HASYIM TEBUIRENG JOMBANG
D4: TAHUN PELAJARAN : 2026- 2027
D6: KELAS : X . 1 | E6: Bulan : __________________________ | S6: Wali Kelas : | U6: LIHAM HASAN AL MUJAB, S.H
B7: NOMOR | D7: NAMA | E7: TANGGAL
B8: URUT | C8: N I S | E8: 17 | G8: =E8+1 -> 18 | I8: =G8+1 -> 19 | K8: =I8+1 -> 20 | M8: =K8+1 -> 21 | O8: =M8+1 -> 22 | Q8: =O8+1 -> 23 | S8: =Q8+1 -> 24 | U8: =S8+1 -> 25 | W8: =U8+1 -> 26 | Y8: =W8+1 -> 27 | AA8: =Y8+1 -> 28 | AC8: =AA8+1 -> 29 | AE8: =AC8+1 -> 30 | AG8: =AE8+1 -> 31 | AI8: =AG8+1 -> 32
E9: jam ke 1 | F9: jam ke 5 | G9: jam ke 1 | H9: jam ke 5 | I9: jam ke 1 | J9: jam ke 5 | K9: jam ke 1 | L9: jam ke 5 | M9: jam ke 1 | N9: jam ke 5 | O9: jam ke 1 | P9: jam ke 5 | Q9: jam ke 1 | R9: jam ke 5 | S9: jam ke 1 | T9: jam ke 5 | U9: jam ke 1 | V9: jam ke 5 | W9: jam ke 1 | X9: jam ke 5 | Y9: jam ke 1 | Z9: jam ke 5 | AA9: jam ke 1 | AB9: jam ke 5 | AC9: jam ke 1 | AD9: jam ke 5 | AE9: jam ke 1 | AF9: jam ke 5 | AG9: jam ke 1 | AH9: jam ke 5 | AI9: jam ke 1 | AJ9: jam ke 5
B10: 1 | C10: ='Kelas X'!C8 -> 16383 | D10: ='Kelas X'!D8 -> ADYPATI NUZHA PUTRA SAFII
B11: =B10+1 -> 2 | C11: ='Kelas X'!C9 -> 16384 | D11: ='Kelas X'!D9 -> ALI AMIRUDIN CAHYO
B12: =B11+1 -> 3 | C12: ='Kelas X'!C10 -> 16385 | D12: ='Kelas X'!D10 -> ANTASENA BANI NATAATMAJA
B13: =B12+1 -> 4 | C13: ='Kelas X'!C11 -> 16386 | D13: ='Kelas X'!D11 -> ARIF HIDAYAT
B14: =B13+1 -> 5 | C14: ='Kelas X'!C12 -> 16387 | D14: ='Kelas X'!D12 -> ARIO ABDILLAH MAZHAZ
B15: =B14+1 -> 6 | C15: ='Kelas X'!C13 -> 16388 | D15: ='Kelas X'!D13 -> BIMA ARYASENO AR-RASYID
B16: =B15+1 -> 7 | C16: ='Kelas X'!C14 -> 16389 | D16: ='Kelas X'!D14 -> DIMAS SAPUTRA
B17: =B16+1 -> 8 | C17: ='Kelas X'!C15 -> 16390 | D17: ='Kelas X'!D15 -> FAITH AZARIA AZFA
B18: =B17+1 -> 9 | C18: ='Kelas X'!C16 -> 16391 | D18: ='Kelas X'!D16 -> IBRAHIM AINUN M
B19: =B18+1 -> 10 | C19: ='Kelas X'!C17 -> 16392 | D19: ='Kelas X'!D17 -> ISNAREJA TURZAITA ZAIN
B20: =B19+1 -> 11 | C20: ='Kelas X'!C18 -> 16393 | D20: ='Kelas X'!D18 -> MAHBUB HAYATULLOH NIDZOMI
B21: =B20+1 -> 12 | C21: ='Kelas X'!C19 -> 16394 | D21: ='Kelas X'!D19 -> MOCH HALIM HILMI
B22: =B21+1 -> 13 | C22: ='Kelas X'!C20 -> 16395 | D22: ='Kelas X'!D20 -> MOCHAMAD VICKY AL FARIZI
... B49: =B48+1 -> 40 | C49: ='Kelas X'!C47 -> 0 | D49: ='Kelas X'!D47 -> 0
B50: =B49+1 -> 41
D53: DAFTAR NAMA SISWA - SISWI
D54: SMA A. WAHID HASYIM TEBUIRENG JOMBANG
D55: TAHUN PELAJARAN : 2026- 2027
D57: KELAS : X. 2 | E57: Bulan : __________________________ | S57: Wali Kelas : | U57: ODIK TUGI HARTONO, S.Pd
B58: NOMOR | D58: NAMA | E58: TANGGAL
B59: URUT | C59: N I S | E59: =E8 -> 17 | G59: =E59+1 -> 18 | I59: =G59+1 -> 19 | K59: =I59+1 -> 20 | M59: =K59+1 -> 21 | O59: =M59+1 -> 22 | Q59: =O59+1 -> 23 | S59: =Q59+1 -> 24 | U59: =S59+1 -> 25 | W59: =U59+1 -> 26 | Y59: =W59+1 -> 27 | AA59: =Y59+1 -> 28 | AC59: =AA59+1 -> 29 | AE59: =AC59+1 -> 30 | AG59: =AE59+1 -> 31 | AI59: =AG59+1 -> 32
E60: jam ke 1 | F60: jam ke 5 | G60: jam ke 1 | H60: jam ke 5 | I60: jam ke 1 | J60: jam ke 5 | K60: jam ke 1 | L60: jam ke 5 | M60: jam ke 1 | N60: jam ke 5 | O60: jam ke 1 | P60: jam ke 5 | Q60: jam ke 1 | R60: jam ke 5 | S60: jam ke 1 | T60: jam ke 5 | U60: jam ke 1 | V60: jam ke 5 | W60: jam ke 1 | X60: jam ke 5 | Y60: jam ke 1 | Z60: jam ke 5 | AA60: jam ke 1 | AB60: jam ke 5 | AC60: jam ke 1 | AD60: jam ke 5 | AE60: jam ke 1 | AF60: jam ke 5 | AG60: jam ke 1 | AH60: jam ke 5 | AI60: jam ke 1 | AJ60: jam ke 5
B61: 1 | C61: ='Kelas X'!C57 -> 16410 | D61: ='Kelas X'!D57 -> AHMAD AZAM NUR ZIDAN
B62: =B61+1 -> 2 | C62: ='Kelas X'!C58 -> 16411 | D62: ='Kelas X'!D58 -> AHMAD DAFA MAULANA
B63: =B62+1 -> 3 | C63: ='Kelas X'!C59 -> 16412 | D63: ='Kelas X'!D59 -> ALEANDRO ILHAM RAMADHAN
B64: =B63+1 -> 4 | C64: ='Kelas X'!C60 -> 16413 | D64: ='Kelas X'!D60 -> AULIA RACHMAN
B65: =B64+1 -> 5 | C65: ='Kelas X'!C61 -> 16414 | D65: ='Kelas X'!D61 -> BIMA SYEHKA ZAELANI
B66: =B65+1 -> 6 | C66: ='Kelas X'!C62 -> 16415 | D66: ='Kelas X'!D62 -> EVAN DESTHA SAPUTRA
B67: =B66+1 -> 7 | C67: ='Kelas X'!C63 -> 16416 | D67: ='Kelas X'!D63 -> FAQIH ARSYAD
B68: =B67+1 -> 8 | C68: ='Kelas X'!C64 -> 16417 | D68: ='Kelas X'!D64 -> FARID AHMAD SATRIA TAMA
B69: =B68+1 -> 9 | C69: ='Kelas X'!C65 -> 16418 | D69: ='Kelas X'!D65 -> FELIX NABIHA RASHAD
B70: =B69+1 -> 10 | C70: ='Kelas X'!C66 -> 16419 | D70: ='Kelas X'!D66 -> HABIB HIDAYATULLAH
B71: =B70+1 -> 11 | C71: ='Kelas X'!C67 -> 16420 | D71: ='Kelas X'!D67 -> IHTISHAM IZAZ NAZMI
...

Sheet Kelas XI
D2: DAFTAR NAMA SISWA - SISWI
D3: SMA A. WAHID HASYIM TEBUIRENG JOMBANG
D4: TAHUN PELAJARAN : 2026- 2027
D5: KELAS : XI .1 | F5: Wali Kelas : YULI KHARISMA DZATI, S.Pd
B6: NOMOR | D6: NAMA | E6: L/P
B7: Urut | C7: N I S
B8: 1 | C8: 16223 | D8: ACHMAD ASYAM HABIBIE PRAKOSO | E8: L
B9: 2 | C9: 16188 | D9: ADITYA ARTHA TRIHUTAMA | E9: L
B10: 3 | C10: 16118 | D10: ADNAN ABIYYU WAJDI | E10: L
B11: 4 | C11: 16189 | D11: AGATHA HARIS SINATHRIA | E11: L
B12: 5 | C12: 16081 | D12: AHMAD WILDAN NUGROHO | E12: L
B13: 6 | C13: 16120 | D13: ALVINNATA SATRIANO | E13: L
B14: 7 | C14: 16086 | D14: AQIL AZZAH | E14: L
B15: 8 | C15: 16087 | D15: ASKAR ADELARD PATU CAHYONO | E15: L
B16: 9 | C16: 16191 | D16: ATHAYA FAJRUL FALAH WITJAKSONO | E16: L
B17: 10 | C17: 16155 | D17: ATMADJA HIBRIZI MUHAMMAD | E17: L
B18: 11 | C18: 16128 | D18: DHOVY HUSYAIN ABDILLAH AL BURHANY | E18: L
B19: 12 | C19: 16158 | D19: DJIO ARNANDO PRATAMA | E19: L
... B41: 34 | C41: 16258 | D41: WILDAN MAULANA | E41: L
B42: 35 | E42: L
B43: 36 | E43: L
B44: 37 | E44: L
B45: 38 | E45: L
B46: 39 | E46: L
B47: 40 | E47: L
B48: 41 | E48: L
D51: DAFTAR NAMA SISWA - SISWI
D52: SMA A. WAHID HASYIM TEBUIRENG JOMBANG
D53: TAHUN PELAJARAN : 2026- 2027
D54: KELAS : XI . 2 | F54: Wali Kelas : EVITRI SUTANTI, S.Si
B55: NOMOR | D55: NAMA | E55: L/P
B56: Urut | C56: N I S
B57: 1 | C57: 16116 | D57: ACHMAD AL AQWAL FEBRIANO NAJJARSYAH | E57: L
B58: 2 | C58: 16117 | D58: ADHWA ENDORA | E58: L
B59: 3 | C59: 16079 | D59: AHMAD DAIROBI | E59: L
B60: 4 | C60: 16224 | D60: AHMAD FAQIH MUHAJIR | E60: L
B61: 5 | C61: 16153 | D61: AHMAD KHOIRUN ALI NABIL | E61: L
B62: 6 | C62: 16082 | D62: AL MULTAZAM YAHYA MUNDHORY | E62: L
B63: 7 | C63: 16154 | D63: ARYO IMRON FAROQ | E63: L
B64: 8 | C64: 16382 | D64: AYDIN ABQARI IKHSAN | E64: L
...

Sheet Absen Piket XI
D2: DAFTAR NAMA SISWA - SISWI
D3: SMA A. WAHID HASYIM TEBUIRENG JOMBANG
D4: TAHUN PELAJARAN : 2026- 2027
D6: KELAS : XI . 1 | E6: Bulan : __________________________ | S6: ='Kelas XI'!F5 -> Wali Kelas : YULI KHARISMA DZATI, S.Pd
B7: NOMOR | D7: NAMA | E7: TANGGAL
B8: URUT | C8: N I S | E8: 17 | G8: =E8+1 -> 18 | I8: =G8+1 -> 19 | K8: =I8+1 -> 20 | M8: =K8+1 -> 21 | O8: =M8+1 -> 22 | Q8: =O8+1 -> 23 | S8: =Q8+1 -> 24 | U8: =S8+1 -> 25 | W8: =U8+1 -> 26 | Y8: =W8+1 -> 27 | AA8: =Y8+1 -> 28 | AC8: =AA8+1 -> 29 | AE8: =AC8+1 -> 30 | AG8: =AE8+1 -> 31 | AI8: =AG8+1 -> 32
E9: jam ke 1 | F9: jam ke 5 | G9: jam ke 1 | H9: jam ke 5 | I9: jam ke 1 | J9: jam ke 5 | K9: jam ke 1 | L9: jam ke 5 | M9: jam ke 1 | N9: jam ke 5 | O9: jam ke 1 | P9: jam ke 5 | Q9: jam ke 1 | R9: jam ke 5 | S9: jam ke 1 | T9: jam ke 5 | U9: jam ke 1 | V9: jam ke 5 | W9: jam ke 1 | X9: jam ke 5 | Y9: jam ke 1 | Z9: jam ke 5 | AA9: jam ke 1 | AB9: jam ke 5 | AC9: jam ke 1 | AD9: jam ke 5 | AE9: jam ke 1 | AF9: jam ke 5 | AG9: jam ke 1 | AH9: jam ke 5 | AI9: jam ke 1 | AJ9: jam ke 5
B10: 1 | C10: ='Kelas XI'!C8 -> 16223 | D10: ='Kelas XI'!D8 -> ACHMAD ASYAM HABIBIE PRAKOSO
B11: =B10+1 -> 2 | C11: ='Kelas XI'!C9 -> 16188 | D11: ='Kelas XI'!D9 -> ADITYA ARTHA TRIHUTAMA
B12: =B11+1 -> 3 | C12: ='Kelas XI'!C10 -> 16118 | D12: ='Kelas XI'!D10 -> ADNAN ABIYYU WAJDI
B13: =B12+1 -> 4 | C13: ='Kelas XI'!C11 -> 16189 | D13: ='Kelas XI'!D11 -> AGATHA HARIS SINATHRIA
B14: =B13+1 -> 5 | C14: ='Kelas XI'!C12 -> 16081 | D14: ='Kelas XI'!D12 -> AHMAD WILDAN NUGROHO
B15: =B14+1 -> 6 | C15: ='Kelas XI'!C13 -> 16120 | D15: ='Kelas XI'!D13 -> ALVINNATA SATRIANO
B16: =B15+1 -> 7 | C16: ='Kelas XI'!C14 -> 16086 | D16: ='Kelas XI'!D14 -> AQIL AZZAH
B17: =B16+1 -> 8 | C17: ='Kelas XI'!C15 -> 16087 | D17: ='Kelas XI'!D15 -> ASKAR ADELARD PATU CAHYONO
B18: =B17+1 -> 9 | C18: ='Kelas XI'!C16 -> 16191 | D18: ='Kelas XI'!D16 -> ATHAYA FAJRUL FALAH WITJAKSONO
B19: =B18+1 -> 10 | C19: ='Kelas XI'!C17 -> 16155 | D19: ='Kelas XI'!D17 -> ATMADJA HIBRIZI MUHAMMAD
B20: =B19+1 -> 11 | C20: ='Kelas XI'!C18 -> 16128 | D20: ='Kelas XI'!D18 -> DHOVY HUSYAIN ABDILLAH AL BURHANY
B21: =B20+1 -> 12 | C21: ='Kelas XI'!C19 -> 16158 | D21: ='Kelas XI'!D19 -> DJIO ARNANDO PRATAMA
B22: =B21+1 -> 13 | C22: ='Kelas XI'!C20 -> 16166 | D22: ='Kelas XI'!D20 -> ILHAM FAUZAN ZAIN
... B50: =B49+1 -> 41 | C50: ='Kelas XI'!C48 -> 0 | D50: ='Kelas XI'!D48 -> 0
D53: DAFTAR NAMA SISWA - SISWI
D54: SMA A. WAHID HASYIM TEBUIRENG JOMBANG
D55: TAHUN PELAJARAN : 2026- 2027
D57: KELAS : XI. 2 | E57: Bulan : __________________________ | S57: ='Kelas XI'!F54 -> Wali Kelas : EVITRI SUTANTI, S.Si
B58: NOMOR | D58: NAMA | E58: TANGGAL
B59: URUT | C59: N I S | E59: =E8 -> 17 | G59: =E59+1 -> 18 | I59: =G59+1 -> 19 | K59: =I59+1 -> 20 | M59: =K59+1 -> 21 | O59: =M59+1 -> 22 | Q59: =O59+1 -> 23 | S59: =Q59+1 -> 24 | U59: =S59+1 -> 25 | W59: =U59+1 -> 26 | Y59: =W59+1 -> 27 | AA59: =Y59+1 -> 28 | AC59: =AA59+1 -> 29 | AE59: =AC59+1 -> 30 | AG59: =AE59+1 -> 31 | AI59: =AG59+1 -> 32
E60: jam ke 1 | F60: jam ke 5 | G60: jam ke 1 | H60: jam ke 5 | I60: jam ke 1 | J60: jam ke 5 | K60: jam ke 1 | L60: jam ke 5 | M60: jam ke 1 | N60: jam ke 5 | O60: jam ke 1 | P60: jam ke 5 | Q60: jam ke 1 | R60: jam ke 5 | S60: jam ke 1 | T60: jam ke 5 | U60: jam ke 1 | V60: jam ke 5 | W60: jam ke 1 | X60: jam ke 5 | Y60: jam ke 1 | Z60: jam ke 5 | AA60: jam ke 1 | AB60: jam ke 5 | AC60: jam ke 1 | AD60: jam ke 5 | AE60: jam ke 1 | AF60: jam ke 5 | AG60: jam ke 1 | AH60: jam ke 5 | AI60: jam ke 1 | AJ60: jam ke 5
B61: 1 | C61: ='Kelas XI'!C57 -> 16116 | D61: ='Kelas XI'!D57 -> ACHMAD AL AQWAL FEBRIANO NAJJARSYAH
B62: =B61+1 -> 2 | C62: ='Kelas XI'!C58 -> 16117 | D62: ='Kelas XI'!D58 -> ADHWA ENDORA
B63: =B62+1 -> 3 | C63: ='Kelas XI'!C59 -> 16079 | D63: ='Kelas XI'!D59 -> AHMAD DAIROBI
B64: =B63+1 -> 4 | C64: ='Kelas XI'!C60 -> 16224 | D64: ='Kelas XI'!D60 -> AHMAD FAQIH MUHAJIR
B65: =B64+1 -> 5 | C65: ='Kelas XI'!C61 -> 16153 | D65: ='Kelas XI'!D61 -> AHMAD KHOIRUN ALI NABIL
B66: =B65+1 -> 6 | C66: ='Kelas XI'!C62 -> 16082 | D66: ='Kelas XI'!D62 -> AL MULTAZAM YAHYA MUNDHORY
B67: =B66+1 -> 7 | C67: ='Kelas XI'!C63 -> 16154 | D67: ='Kelas XI'!D63 -> ARYO IMRON FAROQ
B68: =B67+1 -> 8 | C68: ='Kelas XI'!C64 -> 16382 | D68: ='Kelas XI'!D64 -> AYDIN ABQARI IKHSAN
B69: =B68+1 -> 9 | C69: ='Kelas XI'!C65 -> 16125 | D69: ='Kelas XI'!D65 -> BAGAS KAMIL KHAIRAN
B70: =B69+1 -> 10 | C70: ='Kelas XI'!C66 -> 16156 | D70: ='Kelas XI'!D66 -> DERAHID TRI WICAKSONO
B71: =B70+1 -> 11 | C71: ='Kelas XI'!C67 -> 16129 | D71: ='Kelas XI'!D67 -> DIMAS FAHDIANSYAH
B72: =B71+1 -> 12 | C72: ='Kelas XI'!C68 -> 16159 | D72: ='Kelas XI'!D68 -> FAIZAL AINURROFIQ 'IRFANY
...

Sheet Kelas XII
D2: DAFTAR NAMA SISWA - SISWI
D3: SMA A. WAHID HASYIM TEBUIRENG JOMBANG
D4: TAHUN PELAJARAN : 2026- 2027
D5: KELAS : XII .1 | F5: Wali Kelas : | J5: CAHYONISASI, S.Pd
B6: NOMOR | D6: NAMA | E6: L/P
B7: Urut | C7: N I S
B8: 1 | C8: 15821 | D8: ACHMAD RIFQI ATQI FAHMI | E8: L
B9: 2 | C9: 15927 | D9: AHMAD FELANI NAJMI ZAHRON | E9: L
B10: 3 | C10: 15892 | D10: AKMAL RIDHO HIBATULLOH | E10: L
B11: 4 | C11: 15860 | D11: AKMALUL HIDAYAT FUADZAM SHAH | E11: L
B12: 5 | C12: 15893 | D12: ANDIKA SETYA FIRMANSYAH ADINA PUTRA | E12: L
B13: 6 | C13: 15862 | D13: ATHALLAH FACHRI PRADANA | E13: L
B14: 7 | C14: 15828 | D14: ATTAR FAWWAZ KAMIL | E14: L
B15: 8 | C15: 15896 | D15: FACHRY TEGUH RAMADHAN | E15: L
B16: 9 | C16: 15832 | D16: FADIL MUBAROK | E16: L
B17: 10 | C17: 15864 | D17: FAQIH AKIF ALMAGHRIBI RAHMAT | E17: L
B18: 11 | C18: 15934 | D18: FULVIANO CAHYA MAULANA | E18: L
B19: 12 | C19: 15868 | D19: HAMMAM MUMTAZA | E19: L
... B41: 34 | C41: 15851 | D41: RASYA AUFA NARA HAMIDI | E41: L
B42: 35 | E42: L
B43: 36
D46: DAFTAR NAMA SISWA - SISWI
D47: SMA A. WAHID HASYIM TEBUIRENG JOMBANG
D48: TAHUN PELAJARAN : 2026- 2027
D49: KELAS : XII . 2 | F49: Wali Kelas : | J49: KHOIROTUNNISA', S.Pd
B50: NOMOR | D50: NAMA | E50: L/P
B51: Urut | C51: N I S
B52: 1 | C52: 15822 | D52: ACHMAD TANGSI PUSIRAJA | E52: L
B53: 2 | C53: 15823 | D53: AHMAD FARHAN AL FATIH MASYHURI | E53: L
B54: 3 | C54: 15857 | D54: AHMAD HILMAN WIBAWA PUTRA HIDAYAT | E54: L
B55: 4 | C55: 15929 | D55: AHMAD RAJABI | E55: L
B56: 5 | C56: 15931 | D56: DEFTIAN RIKO PRADITA | E56: L
B57: 6 | C57: 15932 | D57: FAJRUL AKBAR | E57: L
B58: 7 | C58: 15933 | D58: FAUZI MIFTAH PURNASATRIA | E58: L
B59: 8 | C59: 15867 | D59: HAIDAR ALI ZAMANI | E59: L
B60: 9 | C60: 15834 | D60: IQBAL FIRDAUS AL HAMID | E60: L
B61: 10 | C61: 15835 | D61: KENNARD FALAHSYAH | E61: L
B62: 11 | C62: 15870 | D62: KUKUH WICAKSONO | E62: L
B63: 12 | C63: 15871 | D63: LINTANG CAHYA PUTRA | E63: L
... B81: 30 | C81: 15889 | D81: ZHAHER HISMAYA | E81: L
...

Sheet Absen Piket XII
D2: DAFTAR NAMA SISWA - SISWI
D3: SMA A. WAHID HASYIM TEBUIRENG JOMBANG
D4: TAHUN PELAJARAN : 2026- 2027
D6: KELAS : XII . 1 | E6: Bulan : __________________________ | AA6: Wali Kelas : | AC6: CAHYONISASI, S.Pd
B7: NOMOR | D7: NAMA
B8: URUT | C8: N I S | E8: 17 | G8: =E8+1 -> 18 | I8: =G8+1 -> 19 | K8: =I8+1 -> 20 | M8: =K8+1 -> 21 | O8: =M8+1 -> 22 | Q8: =O8+1 -> 23 | S8: =Q8+1 -> 24 | U8: =S8+1 -> 25 | W8: =U8+1 -> 26 | Y8: =W8+1 -> 27 | AA8: =Y8+1 -> 28 | AC8: =AA8+1 -> 29 | AE8: =AC8+1 -> 30 | AG8: =AE8+1 -> 31 | AI8: =AG8+1 -> 32
E9: jam ke 1 | F9: jam ke 5 | G9: jam ke 1 | H9: jam ke 5 | I9: jam ke 1 | J9: jam ke 5 | K9: jam ke 1 | L9: jam ke 5 | M9: jam ke 1 | N9: jam ke 5 | O9: jam ke 1 | P9: jam ke 5 | Q9: jam ke 1 | R9: jam ke 5 | S9: jam ke 1 | T9: jam ke 5 | U9: jam ke 1 | V9: jam ke 5 | W9: jam ke 1 | X9: jam ke 5 | Y9: jam ke 1 | Z9: jam ke 5 | AA9: jam ke 1 | AB9: jam ke 5 | AC9: jam ke 1 | AD9: jam ke 5 | AE9: jam ke 1 | AF9: jam ke 5 | AG9: jam ke 1 | AH9: jam ke 5 | AI9: jam ke 1 | AJ9: jam ke 5
B10: 1 | C10: ='Kelas XII'!C8 -> 15821 | D10: ='Kelas XII'!D8 -> ACHMAD RIFQI ATQI FAHMI
B11: =B10+1 -> 2 | C11: ='Kelas XII'!C9 -> 15927 | D11: ='Kelas XII'!D9 -> AHMAD FELANI NAJMI ZAHRON
B12: =B11+1 -> 3 | C12: ='Kelas XII'!C10 -> 15892 | D12: ='Kelas XII'!D10 -> AKMAL RIDHO HIBATULLOH
B13: =B12+1 -> 4 | C13: ='Kelas XII'!C11 -> 15860 | D13: ='Kelas XII'!D11 -> AKMALUL HIDAYAT FUADZAM SHAH
B14: =B13+1 -> 5 | C14: ='Kelas XII'!C12 -> 15893 | D14: ='Kelas XII'!D12 -> ANDIKA SETYA FIRMANSYAH ADINA PUTRA
B15: =B14+1 -> 6 | C15: ='Kelas XII'!C13 -> 15862 | D15: ='Kelas XII'!D13 -> ATHALLAH FACHRI PRADANA
B16: =B15+1 -> 7 | C16: ='Kelas XII'!C14 -> 15828 | D16: ='Kelas XII'!D14 -> ATTAR FAWWAZ KAMIL
B17: =B16+1 -> 8 | C17: ='Kelas XII'!C15 -> 15896 | D17: ='Kelas XII'!D15 -> FACHRY TEGUH RAMADHAN
B18: =B17+1 -> 9 | C18: ='Kelas XII'!C16 -> 15832 | D18: ='Kelas XII'!D16 -> FADIL MUBAROK
B19: =B18+1 -> 10 | C19: ='Kelas XII'!C17 -> 15864 | D19: ='Kelas XII'!D17 -> FAQIH AKIF ALMAGHRIBI RAHMAT
B20: =B19+1 -> 11 | C20: ='Kelas XII'!C18 -> 15934 | D20: ='Kelas XII'!D18 -> FULVIANO CAHYA MAULANA
B21: =B20+1 -> 12 | C21: ='Kelas XII'!C19 -> 15868 | D21: ='Kelas XII'!D19 -> HAMMAM MUMTAZA
B22: =B21+1 -> 13 | C22: ='Kelas XII'!C20 -> 15869 | D22: ='Kelas XII'!D20 -> IBRA HAIDAR ALI
... B46: =B45+1 -> 37 | C46: ='Kelas XII'!C44 -> 0 | D46: ='Kelas XII'!D44 -> 0
D49: DAFTAR NAMA SISWA - SISWI
D50: SMA A. WAHID HASYIM TEBUIRENG JOMBANG
D51: TAHUN PELAJARAN : 2026- 2027
D53: KELAS : XII. 2 | E53: Bulan : __________________________ | AA53: Wali Kelas : | AC53: KHOIROTUNNISA', S.Pd
B54: NOMOR | D54: NAMA
B55: URUT | C55: N I S | E55: =E8 -> 17 | G55: =E55+1 -> 18 | I55: =G55+1 -> 19 | K55: =I55+1 -> 20 | M55: =K55+1 -> 21 | O55: =M55+1 -> 22 | Q55: =O55+1 -> 23 | S55: =Q55+1 -> 24 | U55: =S55+1 -> 25 | W55: =U55+1 -> 26 | Y55: =W55+1 -> 27 | AA55: =Y55+1 -> 28 | AC55: =AA55+1 -> 29 | AE55: =AC55+1 -> 30 | AG55: =AE55+1 -> 31 | AI55: =AG55+1 -> 32
E56: jam ke 1 | F56: jam ke 5 | G56: jam ke 1 | H56: jam ke 5 | I56: jam ke 1 | J56: jam ke 5 | K56: jam ke 1 | L56: jam ke 5 | M56: jam ke 1 | N56: jam ke 5 | O56: jam ke 1 | P56: jam ke 5 | Q56: jam ke 1 | R56: jam ke 5 | S56: jam ke 1 | T56: jam ke 5 | U56: jam ke 1 | V56: jam ke 5 | W56: jam ke 1 | X56: jam ke 5 | Y56: jam ke 1 | Z56: jam ke 5 | AA56: jam ke 1 | AB56: jam ke 5 | AC56: jam ke 1 | AD56: jam ke 5 | AE56: jam ke 1 | AF56: jam ke 5 | AG56: jam ke 1 | AH56: jam ke 5 | AI56: jam ke 1 | AJ56: jam ke 5
B57: 1 | C57: ='Kelas XII'!C52 -> 15822 | D57: ='Kelas XII'!D52 -> ACHMAD TANGSI PUSIRAJA
B58: =B57+1 -> 2 | C58: ='Kelas XII'!C53 -> 15823 | D58: ='Kelas XII'!D53 -> AHMAD FARHAN AL FATIH MASYHURI
B59: =B58+1 -> 3 | C59: ='Kelas XII'!C54 -> 15857 | D59: ='Kelas XII'!D54 -> AHMAD HILMAN WIBAWA PUTRA HIDAYAT
B60: =B59+1 -> 4 | C60: ='Kelas XII'!C55 -> 15929 | D60: ='Kelas XII'!D55 -> AHMAD RAJABI
B61: =B60+1 -> 5 | C61: ='Kelas XII'!C56 -> 15931 | D61: ='Kelas XII'!D56 -> DEFTIAN RIKO PRADITA
B62: =B61+1 -> 6 | C62: ='Kelas XII'!C57 -> 15932 | D62: ='Kelas XII'!D57 -> FAJRUL AKBAR
B63: =B62+1 -> 7 | C63: ='Kelas XII'!C58 -> 15933 | D63: ='Kelas XII'!D58 -> FAUZI MIFTAH PURNASATRIA
B64: =B63+1 -> 8 | C64: ='Kelas XII'!C59 -> 15867 | D64: ='Kelas XII'!D59 -> HAIDAR ALI ZAMANI
B65: =B64+1 -> 9 | C65: ='Kelas XII'!C60 -> 15834 | D65: ='Kelas XII'!D60 -> IQBAL FIRDAUS AL HAMID
B66: =B65+1 -> 10 | C66: ='Kelas XII'!C61 -> 15835 | D66: ='Kelas XII'!D61 -> KENNARD FALAHSYAH
B67: =B66+1 -> 11 | C67: ='Kelas XII'!C62 -> 15870 | D67: ='Kelas XII'!D62 -> KUKUH WICAKSONO
B68: =B67+1 -> 12 | C68: ='Kelas XII'!C63 -> 15871 | D68: ='Kelas XII'!D63 -> LINTANG CAHYA PUTRA
...
